<?xml version="1.0"?>
<robot name="simple_biped">

  <!-- Root link -->
  <link name="torso"/>

  <!-- ================= RIGHT LEG ================= -->
  <link name="right_thigh"/>
  <link name="right_shin"/>

  <joint name="right_hip" type="revolute">
    <parent link="torso"/>
    <child link="right_thigh"/>
    <origin xyz="0 -0.1 -0.3" rpy="0 0 0"/>
    <axis xyz="0 1 0"/>
    <limit lower="-1.0" upper="1.0" effort="100" velocity="10"/>
  </joint>

  <joint name="right_knee" type="revolute">
    <parent link="right_thigh"/>
    <child link="right_shin"/>
    <origin xyz="0 0 -0.6" rpy="0 0 0"/>
    <axis xyz="0 1 0"/>
    <limit lower="-1.5" upper="0.0" effort="100" velocity="10"/>
  </joint>

  <!-- ================= LEFT LEG ================= -->
  <link name="left_thigh"/>
  <link name="left_shin"/>

  <joint name="left_hip" type="revolute">
    <parent link="torso"/>
    <child link="left_thigh"/>
    <origin xyz="0 0.1 -0.3" rpy="0 0 0"/>
    <axis xyz="0 1 0"/>
    <limit lower="-1.0" upper="1.0" effort="100" velocity="10"/>
  </joint>

  <joint name="left_knee" type="revolute">
    <parent link="left_thigh"/>
    <child link="left_shin"/>
    <origin xyz="0 0 -0.6" rpy="0 0 0"/>
    <axis xyz="0 1 0"/>
    <limit lower="-1.5" upper="0.0" effort="100" velocity="10"/>
  </joint>

</robot>
